<?xml version="1.0" ?>
<sdf version="1.5">
    <model name="payload">
    <static>false</static>
    
    <joint name="world_base" type="fixed">
        <parent>world</parent>
        <child>base</child>
    </joint>

    <link name="base">        
        <pose>0 0 0.25 0 0 0</pose>

        <collision name="collision">
            <geometry>
                <box>
                  <size>2.0 2.0 0.5</size>
                </box>
            </geometry>
        </collision>
        
        <visual name="visual">
            <geometry>
                <box>
                  <size>2.0 2.0 0.5</size>
                </box>
            </geometry>
            <material>
                <script>
                    <!-- <uri>model://payload/materials/scripts</uri>
                    <uri>model://payload/materials/textures</uri>
                    <name>base/asphalt</name> -->
                    <uri>file://media/materials/scripts/gazebo.material</uri>
                    <name>Gazebo/DarkGrey</name>
                </script>
            </material>
        </visual>
    </link>

    <include>
        <uri>model://extendable_mast/</uri>
        <pose>0 0 1 0 0 0</pose>
    </include>

    <joint name="base_to_mast" type="prismatic">

        <parent>base</parent>
        <child>extendable_mast::em_mast</child>

        <axis>
            <xyz>
                0.0 0.0 1.0
            </xyz>
            <dynamics>
                <damping>0.05</damping>
                <friction>0.05</friction>
            </dynamics>
            <limit>
                <lower>0.0</lower>
                <upper>2.5</upper>
            </limit>
        </axis>

    </joint>

    <joint name="base_to_mast_cylinder" type="fixed">
        <parent>base</parent>
        <child>extendable_mast::em_mast_cylinder</child>
    </joint>

    <include>
        <uri>model://sensor_mount/</uri>
        <pose>0 0 1.95 0 0 0</pose>
    </include>

    <joint name="mast_sensor_mount" type="revolute">
        <parent>extendable_mast::em_mast</parent>
        <child>sensor_mount::sensor_mount_base</child>
        <axis>
            <xyz>
                0.0 0.0 1.0
            </xyz>
            <dynamics>
                <damping>0.05</damping>
                <friction>1.05</friction>
            </dynamics>
            <limit>
                <!-- 15 rad/s -->
                <velocity>0.261799</velocity>
            </limit>
        </axis>
    </joint>

    <include>
        <uri>model://camera_with_lrf/</uri>
        <pose>0.55 0 2.25 1.5707 0 0</pose>
    </include>

    <joint name="daylight_camera_tilt" type="revolute">
        <parent>sensor_mount::sensor_mount_base</parent>
        <child>camera_with_lrf::cwlrf_camera</child>
        <axis>
            <xyz>
                1.0 0.0 0.0
            </xyz>
            <limit>
                <!-- 15 rad/s -->
                <velocity>0.261799</velocity>
                <lower>-1.57</lower>
                <upper>1.57</upper>
            </limit>
            <dynamics>
                <damping>0.05</damping>
                <friction>1.05</friction>
            </dynamics>
        </axis>
    </joint>
    
  </model>
</sdf>