<?xml version="1.0" ?>
<sdf version="1.5">
    <model name="extendable_mast">
        <static>false</static>

        <link name="em_base_phantom">
            <pose>0 0 0   0 0 0</pose>
        </link>


        <joint name="em_base_phantom_to_fixed_base" type="fixed">
            <parent>em_base_phantom</parent>
            <child>em_fixed_base</child>
        </joint>

        <link name="em_fixed_base">

            <!-- <collision name="collision">
                <geometry>
                    <box>
                        <size>0.1 0.1 1.0</size>
                    </box>
                </geometry>
            </collision> -->
            
            <visual name="visual">
                <geometry>
                    <box>
                        <size>0.1 0.1 1.0</size>
                    </box>
                </geometry>
                <material>
                    <script>
                        <uri>file://media/materials/scripts/gazebo.material</uri>
                        <name>Gazebo/Grey</name>
                    </script>
                </material>
            </visual>
            
        </link>

        <joint name="em_seg1_lift" type="prismatic">
            <parent>em_fixed_base</parent>
            <child>em_seg_1</child>

            <axis>
                <xyz>
                    0.0 0.0 1.0
                </xyz>
                <dynamics>
                    <damping>0.05</damping>
                    <friction>0.05</friction>
                </dynamics>
                <limit>
                    <!-- Keeping the upper limit 25% higher than what's expected should move things as desired -->
                    <lower>0.0</lower>
                    <upper>1.2</upper> 
                </limit>
            </axis>

        </joint>

        <link name="em_seg_1">

            <!-- mast must have a weight to let PID controller work-->
            <intertial>
                <mass>5</mass>
            </intertial>

            <!-- <collision name="collision">
                <geometry>
                    <box>
                        <size>0.1 0.1 1.0</size>
                    </box>
                </geometry>
            </collision> -->
            
            <visual name="visual">
                <geometry>
                    <box>
                        <size>0.1 0.1 1.0</size>
                    </box>
                </geometry>
                <material>
                    <script>
                        <uri>file://media/materials/scripts/gazebo.material</uri>
                        <name>Gazebo/Grey</name>
                    </script>
                </material>
            </visual>
            
        </link>


        <joint name="em_seg2_lift" type="prismatic">

            <pose relative_to="em_seg_1">0 0 0   0 0 0</pose>

            <parent>em_seg_1</parent>
            <child>em_seg_2</child>

            <axis>
                <xyz>
                    0.0 0.0 1.0
                </xyz>
                <dynamics>
                    <damping>0.05</damping>
                    <friction>0.05</friction>
                </dynamics>
                <limit>
                    <!-- Keeping the upper limit 25% higher than what's expected should move things as desired -->
                    <lower>0.0</lower>
                    <upper>1.2</upper>
                </limit>
            </axis>

        </joint>

        <link name="em_seg_2">

            <pose relative_to="em_seg_1">0 0 0   0 0 0</pose>

            <intertial>
                <mass>5</mass>
            </intertial>

            <!-- <collision name="collision">
                <geometry>
                    <box>
                        <size>0.1 0.1 1.0</size>
                    </box>
                </geometry>
            </collision> -->
            
            <visual name="visual">

                <geometry>
                    <box>
                        <size>0.1 0.1 1.0</size>
                    </box>
                </geometry>em_seg_2
                <material>
                    <script>
                        <uri>file://media/materials/scripts/gazebo.material</uri>
                        <name>Gazebo/Red</name>
                    </script>
                </material>
            </visual>
            
        </link>

        <joint name="em_seg_2_to_em_top_mount_phantom" type="fixed">
            <parent>em_seg_2</parent>
            <child>em_top_mount_phantom</child>
        </joint>


        <link name="em_top_mount_phantom">
            <pose relative_to="em_seg_2">0 0 0.5   0 0 0</pose>

            <intertial>
                <mass>50</mass>
            </intertial>

            <visual name="visual">
                <geometry>
                    <box>
                        <size>0.25 0.25 0.02</size>
                    </box>
                </geometry>
            </visual>
        </link>
        

        <plugin name="extendable_mast_controller" filename="libextendable_mast_controller.so">
            <topic_name_sub_cmds>
                mast_command
            </topic_name_sub_cmds>
            
            <topic_name_pub_status>
                mast_status
            </topic_name_pub_status>
            
            <link_name_segment_mount>
                em_top_mount_phantom
            </link_name_segment_mount>

            <joint_lift_seg_1>
                em_seg1_lift
            </joint_lift_seg_1>

            <joint_lift_seg_2>
                em_seg2_lift
            </joint_lift_seg_2>

            <joint_lift_seg_1_pid>
                450.0 100.0 100.0
            </joint_lift_seg_1_pid>

            <joint_lift_seg_2_pid>
                450.0 100.0 100.0
            </joint_lift_seg_2_pid>
            
            <step_height>0.02</step_height>

            <publish_rate>4</publish_rate>
            <reported_min_height>1.0</reported_min_height>
            <reported_max_height>3.0</reported_max_height>
        </plugin>
    </model>
</sdf>